Workbook

Sheet Foglio di CALCOLO
A1: Negozio x
A2: LUGLIO
A3: Date | C3: Sales | D3: Budget | E3: Idx To Budget | G3: WON/ LOST | I3: Salest LY | J3: Idx Sales LY | K3: WON/ LOST (LY)
A4: W27
A5: Mercoledì | B5: 46204 | C5: 933 | D5: 1215 | E5: =C5/D5 -> 0.76790123 | G5: =C5-D5 -> -282 | I5: 1226 | J5: =C5/I5 -> 0.76101142 | K5: =+C5-I5 -> -293
A6: Giovedì | B6: 46205 | C6: 1432 | D6: 1126 | E6: =C6/D6 -> 1.2717584 | G6: =C6-D6 -> 306 | I6: 849 | J6: =C6/I6 -> 1.6866902 | K6: =+C6-I6 -> 583
A7: Venerdì | B7: 46206 | C7: 1331 | D7: 1295 | E7: =C7/D7 -> 1.0277992 | G7: =C7-D7 -> 36 | I7: 1074 | J7: =C7/I7 -> 1.2392924 | K7: =+C7-I7 -> 257
A8: Sabato | B8: 46207 | C8: 3256 | D8: 5437 | E8: =C8/D8 -> 0.59885967 | G8: =C8-D8 -> -2181 | I8: 4247 | J8: =C8/I8 -> 0.76665882 | K8: =+C8-I8 -> -991
A9: Domenica | B9: 46208 | C9: 2011 | D9: 6311 | E9: =C9/D9 -> 0.31864998 | G9: =C9-D9 -> -4300 | I9: 4038 | J9: =C9/I9 -> 0.49801882 | K9: =+C9-I9 -> -2027
A10: W28 | B10: 28 | C10: =SUM(C5:C9) -> 8963 | D10: =SUM(D5:D9) -> 15384 | E10: =C10/D10 -> 0.5826183 | G10: =C10-D10 -> -6421 | I10: =SUM(I5:I9) -> 11434 | J10: =C10/I10 -> 0.78389015 | K10: =SUM(K5:K9) -> -2471
A11: Lunedì | B11: 46209 | C11: 1603 | D11: 2320 | E11: =C11/D11 -> 0.69094828 | G11: =C11-D11 -> -717 | I11: 1611 | J11: =C11/I11 -> 0.99503414 | K11: =+C11-I11 -> -8
A12: Martedì | B12: 46210 | C12: 1542 | D12: 2024 | E12: =C12/D12 -> 0.76185771 | G12: =C12-D12 -> -482 | I12: 1518 | J12: =C12/I12 -> 1.0158103 | K12: =+C12-I12 -> 24
A13: Mercoledì | B13: 46211 | C13: 1483.1 | D13: 1806 | E13: =C13/D13 -> 0.82120709 | G13: =C13-D13 -> -322.9 | I13: 1654 | J13: =C13/I13 -> 0.89667473 | K13: =+C13-I13 -> -170.9
A14: Giovedì | B14: 46212 | C14: 1735 | D14: 1747 | E14: =C14/D14 -> 0.99313108 | G14: =C14-D14 -> -12 | I14: 1271 | J14: =C14/I14 -> 1.3650669 | K14: =+C14-I14 -> 464
A15: Venerdì | B15: 46213 | C15: 1727 | D15: 1852 | E15: =C15/D15 -> 0.9325054 | G15: =C15-D15 -> -125 | I15: 1526 | J15: =C15/I15 -> 1.1317169 | K15: =+C15-I15 -> 201
A16: Sabato | B16: 46214 | C16: 3687 | D16: 4262 | E16: =C16/D16 -> 0.86508681 | G16: =C16-D16 -> -575 | I16: 3047 | J16: =C16/I16 -> 1.2100427 | K16: =+C16-I16 -> 640
A17: Domenica | B17: 46215 | C17: 2803 | D17: 5615 | E17: =C17/D17 -> 0.49919858 | G17: =C17-D17 -> -2812 | I17: 3560 | J17: =C17/I17 -> 0.78735955 | K17: =+C17-I17 -> -757
A18: W29 | B18: 29 | C18: =SUM(C11:C17) -> 14580.1 | D18: =SUM(D11:D17) -> 19626 | E18: =C18/D18 -> 0.74289718 | G18: =C18-D18 -> -5045.9 | I18: =SUM(I11:I17) -> 14187 | J18: =C18/I18 -> 1.0277085 | K18: =SUM(K11:K17) -> 393.1
A19: Lunedì | B19: 46216 | C19: 1245 | D19: 1626 | E19: =C19/D19 -> 0.76568266 | G19: =C19-D19 -> -381 | I19: 1523 | J19: =C19/I19 -> 0.81746553 | K19: =+C19-I19 -> -278
A20: Martedì | B20: 46217 | C20: 1232 | D20: 1561 | E20: =C20/D20 -> 0.78923767 | G20: =C20-D20 -> -329 | I20: 2418 | J20: =C20/I20 -> 0.50951199 | K20: =+C20-I20 -> -1186
A21: Mercoledì | B21: 46218 | C21: 1525 | D21: 1680 | E21: =C21/D21 -> 0.9077381 | G21: =C21-D21 -> -155 | I21: 2581 | J21: =C21/I21 -> 0.59085626 | K21: =+C21-I21 -> -1056
A22: Giovedì | B22: 46219 | C22: 1841 | D22: 1548 | E22: =C22/D22 -> 1.1892765 | G22: =C22-D22 -> 293 | I22: 1564 | J22: =C22/I22 -> 1.17711 | K22: =+C22-I22 -> 277
A23: Venerdì | B23: 46220 | C23: 1257 | D23: 1597 | E23: =C23/D23 -> 0.78710081 | G23: =C23-D23 -> -340 | I23: 1498 | J23: =C23/I23 -> 0.83911883 | K23: =+C23-I23 -> -241
A24: Sabato | B24: 46221 | C24: 3374 | D24: 3742 | E24: =C24/D24 -> 0.90165687 | G24: =C24-D24 -> -368 | I24: 2968 | J24: =C24/I24 -> 1.1367925 | K24: =+C24-I24 -> 406
A25: Domenica | B25: 46222 | C25: 2167 | D25: 4136 | E25: =C25/D25 -> 0.52393617 | G25: =C25-D25 -> -1969 | I25: 3161 | J25: =C25/I25 -> 0.68554255 | K25: =+C25-I25 -> -994
A26: W30 | B26: 30 | C26: =SUM(C19:C25) -> 12641 | D26: =SUM(D19:D25) -> 15890 | E26: =C26/D26 -> 0.79553178 | G26: =C26-D26 -> -3249 | I26: =SUM(I19:I25) -> 15713 | J26: =C26/I26 -> 0.80449309 | K26: =SUM(K19:K25) -> -3072
A27: Lunedì | B27: 46223 | C27: 1400 | D27: 1642 | E27: =C27/D27 -> 0.85261876 | G27: =C27-D27 -> -242 | I27: 943 | J27: =C27/I27 -> 1.4846235 | K27: =+C27-I27 -> 457
A28: Martedì | B28: 46224 | C28: 910 | D28: 1323 | E28: =C28/D28 -> 0.68783069 | G28: =C28-D28 -> -413 | I28: 1516 | J28: =C28/I28 -> 0.60026385 | K28: =+C28-I28 -> -606
A29: Mercoledì | B29: 46225 | C29: 1004 | D29: 1497 | E29: =C29/D29 -> 0.67067468 | G29: =C29-D29 -> -493 | I29: 2015 | J29: =C29/I29 -> 0.49826303 | K29: =+C29-I29 -> -1011
A30: Giovedì | B30: 46226 | C30: 1388 | D30: 1614 | E30: =C30/D30 -> 0.85997522 | G30: =C30-D30 -> -226 | I30: 1436 | J30: =C30/I30 -> 0.96657382 | K30: =+C30-I30 -> -48
A31: Venerdì | B31: 46227 | C31: 1588 | D31: 1855 | E31: =C31/D31 -> 0.85606469 | G31: =C31-D31 -> -267 | I31: 1385 | J31: =C31/I31 -> 1.1465704 | K31: =+C31-I31 -> 203
A32: Sabato | B32: 46228 | C32: 2782 | D32: 3854 | E32: =C32/D32 -> 0.72184743 | G32: =C32-D32 -> -1072 | I32: 4371 | J32: =C32/I32 -> 0.63646763 | K32: =+C32-I32 -> -1589
A33: Domenica | B33: 46229 | C33: 3292 | D33: 3630 | E33: =C33/D33 -> 0.90688705 | G33: =C33-D33 -> -338 | H33: x | I33: 3404 | J33: =C33/I33 -> 0.96709753 | K33: =+C33-I33 -> -112
A34: W31 | B34: 31 | C34: =SUM(C27:C33) -> 12364 | D34: =SUM(D27:D33) -> 15415 | E34: =C34/D34 -> 0.8020759 | G34: =C34-D34 -> -3051 | I34: =SUM(I27:I33) -> 15070 | J34: =C34/I34 -> 0.82043796 | K34: =SUM(K27:K33) -> -2706
A35: Lunedì | B35: 46230 | C35: 1317 | D35: 2154 | E35: =C35/D35 -> 0.61142061 | G35: =C35-D35 -> -837 | I35: 1387 | J35: =C35/I35 -> 0.94953136 | K35: =+C35-I35 -> -70
A36: Martedì | B36: 46231 | C36: 869 | D36: 1319 | E36: =C36/D36 -> 0.65883245 | G36: =C36-D36 -> -450 | I36: 1308 | J36: =C36/I36 -> 0.66437309 | K36: =+C36-I36 -> -439
A37: Mercoledì | B37: 46232 | C37: 663 | D37: 1313 | E37: =C37/D37 -> 0.5049505 | G37: =C37-D37 -> -650 | I37: 1582 | J37: =C37/I37 -> 0.41908976 | K37: =+C37-I37 -> -919
A38: Giovedì | B38: 46233 | C38: 894 | D38: 1245 | E38: =C38/D38 -> 0.71807229 | G38: =C38-D38 -> -351 | I38: 1114 | J38: =C38/I38 -> 0.80251346 | K38: =+C38-I38 -> -220
A39: Venerdì | B39: 46234 | C39: 1964 | D39: 1525 | E39: =C39/D39 -> 1.2878689 | G39: =C39-D39 -> 439 | I39: 2024 | J39: =C39/I39 -> 0.97035573 | K39: =+C39-I39 -> -60
C40: =SUM(C35:C39) -> 5707 | D40: =SUM(D35:D39) -> 7556 | E40: =C40/D40 -> 0.75529381 | G40: =C40-D40 -> -1849 | I40: =SUM(I35:I39) -> 7415 | J40: =C40/I40 -> 0.7696561 | K40: =SUM(K35:K39) -> -1708
...

Sheet POWERPOINT
A1: Budget GAP - LUGLIO
B2: Sales | C2: Target | D2: LY | E2: GAP | G2: Budget GAP
A3: W27 | B3: =+'Foglio di CALCOLO'!C10 -> 8963 | C3: =+'Foglio di CALCOLO'!D10 -> 15384 | D3: ='Foglio di CALCOLO'!I10 -> 11434 | E3: =B3-C3 -> -6421
A4: W28 | B4: =+'Foglio di CALCOLO'!C18 -> 14580.1 | C4: =+'Foglio di CALCOLO'!D18 -> 19626 | D4: =+'Foglio di CALCOLO'!I18 -> 14187 | E4: =B4-C4 -> -5045.9
A5: W29 | B5: =+'Foglio di CALCOLO'!C26 -> 12641 | C5: =+'Foglio di CALCOLO'!D26 -> 15890 | D5: =+'Foglio di CALCOLO'!I26 -> 15713 | E5: =B5-C5 -> -3249
A6: W30 | B6: =+'Foglio di CALCOLO'!C34 -> 12364 | C6: =+'Foglio di CALCOLO'!D34 -> 15415 | D6: =+'Foglio di CALCOLO'!I34 -> 15070 | E6: =B6-C6 -> -3051
A7: W31 | B7: =+'Foglio di CALCOLO'!C40 -> 5707 | C7: =+'Foglio di CALCOLO'!D40 -> 7556 | D7: =+'Foglio di CALCOLO'!I40 -> 7415 | E7: =B7-C7 -> -1849
B8: =SUM(B3:B7) -> 54255.1 | C8: =SUM(C3:C7) -> 73871 | D8: =SUM(D3:D7) -> 63819 | E8: =SUM(E3:E7) -> -19615.9
B9: Raggiunto | C9: =B8/C8 -> 0.73445736 | D9: =B8/D8 -> 0.85014024
B10: Mancante | C10: =1-C9 -> 0.26554264 | D10: =1-D9 -> 0.14985976
G13: Weekly Trend

Sheet Foglio3
